<?xml version="1.0"?>
<robot xmlns:xacro="http://ros.org/wiki/xacro" name="vector_linear_actuator">

	<xacro:macro name="poli_linear_actuator" params="parent *origin">
        
        
        <joint name="linear_actuator_joint" type="fixed">
            <xacro:insert_block name="origin" />
            <parent link="${parent}" />
            <child link="linear_actuator_fixed_link" />
        </joint>
        
	    <link name="linear_actuator_fixed_link">
			<visual>
                <origin xyz="0 0 0" rpy="0 0 0"/>
				  <geometry>
					<mesh filename="package://poli_description/meshes/base_link.STL" />
				</geometry>
			</visual>
			<collision>
				<geometry>
					<mesh filename="package://poli_description/meshes/base_link.STL" />
				</geometry>
			</collision>
            <inertial>
              <origin xyz="-0.011801 0.024796 -0.63503" rpy="0 0 0" />
              <mass value="19.332" />
              <inertia
                ixx="2.4716"
                ixy="-0.0011724"
                ixz="0.0085341"
                iyy="2.4326"
                iyz="-0.17433"
                izz="0.066996" />
            </inertial>

		    <!--inertial>
                <mass value="5.098044" />
                <origin xyz="0.0 0.0 0.5" rpy="0 0 0"/>
                <inertia ixx="0.02"  ixy="0.0"  ixz="1.0" iyy="-0.03"  iyz="-0.02" izz="0.0" />
		    </inertial-->			    
		</link>

        <joint name="linear_joint" type="prismatic">
          <!--origin xyz="0.038771 -0.000254 -0.10409" rpy="0 0 0" /-->
          <origin xyz="0.0377 -0.000254 -0.904" rpy="0 0 0" />
          <parent link="linear_actuator_fixed_link" />
          <child link="linear_actuator_link" />
          <axis xyz="0 0 1" />
          <limit lower="0.0" upper="0.70" effort="1000" velocity="0.20"/>
          <dynamics damping="0.0" friction="0.0"/>
        </joint>
        
        <link name="linear_actuator_link">
            <visual>
                <origin xyz="-0.010983 -2.4672E-08 -1.3117E-08" rpy="0 0 0" />
                <geometry>
                    <mesh filename="package://vector_description/meshes/linear_actuator/visual/linear_carraige.dae" />
                </geometry>
            </visual>
            <collision>
                <origin xyz="-0.010983 -2.4672E-08 -1.3117E-08" rpy="0 0 0" />
                <geometry>
                    <mesh filename="package://vector_description/meshes/linear_actuator/collision/linear_carraige_collision.STL" />
                </geometry>
            </collision>
            <inertial>
              <origin xyz="-0.010983 -2.4672E-08 -1.3117E-08" rpy="0 0 0" />
              <mass value="1.6935" />
              <inertia
                ixx="0.0045057"
                ixy="-1.053E-10"
                ixz="-1.6253E-10"
                iyy="0.0040599"
                iyz="2.4585E-08"
                izz="0.00063223" />
            </inertial>
        </link>

        <transmission name="linear_trans">
            <type>transmission_interface/SimpleTransmission</type>
            <joint name="linear_joint">
                <hardwareInterface>PositionJointInterface</hardwareInterface>
            </joint>
            <actuator name="linear_motor">
                <mechanicalReduction>1</mechanicalReduction>
            </actuator>
        </transmission>             
   
    </xacro:macro>

</robot>
